01_08_2025 - group argument must be None for now
01_08_2025 - group argument must be None for now 
01_08_2025 - group argument must be None for now
01_09_2025 | anaplasma - Traceback (most recent call last):
  File "C:\Users\caleb.jones\Repos\nbsbot\env\Lib\site-packages\urllib3\connection.py", line 199, in _new_conn
    sock = connection.create_connection(
        (self._dns_host, self.port),
    ...<2 lines>...
        socket_options=self.socket_options,
    )
  File "C:\Users\caleb.jones\Repos\nbsbot\env\Lib\site-packages\urllib3\util\connection.py", line 85, in create_connection
    raise err
  File "C:\Users\caleb.jones\Repos\nbsbot\env\Lib\site-packages\urllib3\util\connection.py", line 73, in create_connection
    sock.connect(sa)
    ~~~~~~~~~~~~^^^^
ConnectionRefusedError: [WinError 10061] No connection could be made because the target machine actively refused it

The above exception was the direct cause of the following exception:

Traceback (most recent call last):
  File "C:\Users\caleb.jones\Repos\nbsbot\env\Lib\site-packages\urllib3\connectionpool.py", line 789, in urlopen
    response = self._make_request(
        conn,
    ...<10 lines>...
        **response_kw,
    )
  File "C:\Users\caleb.jones\Repos\nbsbot\env\Lib\site-packages\urllib3\connectionpool.py", line 495, in _make_request
    conn.request(
    ~~~~~~~~~~~~^
        method,
        ^^^^^^^
    ...<6 lines>...
        enforce_content_length=enforce_content_length,
        ^^^^^^^^^^^^^^^^^^^^^^^^^^^^^^^^^^^^^^^^^^^^^^
    )
    ^
  File "C:\Users\caleb.jones\Repos\nbsbot\env\Lib\site-packages\urllib3\connection.py", line 441, in request
    self.endheaders()
    ~~~~~~~~~~~~~~~^^
  File "C:\Users\caleb.jones\AppData\Local\Programs\Python\Python313\Lib\http\client.py", line 1331, in endheaders
    self._send_output(message_body, encode_chunked=encode_chunked)
    ~~~~~~~~~~~~~~~~~^^^^^^^^^^^^^^^^^^^^^^^^^^^^^^^^^^^^^^^^^^^^^
  File "C:\Users\caleb.jones\AppData\Local\Programs\Python\Python313\Lib\http\client.py", line 1091, in _send_output
    self.send(msg)
    ~~~~~~~~~^^^^^
  File "C:\Users\caleb.jones\AppData\Local\Programs\Python\Python313\Lib\http\client.py", line 1035, in send
    self.connect()
    ~~~~~~~~~~~~^^
  File "C:\Users\caleb.jones\Repos\nbsbot\env\Lib\site-packages\urllib3\connection.py", line 279, in connect
    self.sock = self._new_conn()
                ~~~~~~~~~~~~~~^^
  File "C:\Users\caleb.jones\Repos\nbsbot\env\Lib\site-packages\urllib3\connection.py", line 214, in _new_conn
    raise NewConnectionError(
        self, f"Failed to establish a new connection: {e}"
    ) from e
urllib3.exceptions.NewConnectionError: <urllib3.connection.HTTPConnection object at 0x000001F7842F6EA0>: Failed to establish a new connection: [WinError 10061] No connection could be made because the target machine actively refused it

The above exception was the direct cause of the following exception:

Traceback (most recent call last):
  File "C:\Users\caleb.jones\Repos\nbsbot\RevisedBots\anaplasma.py", line 61, in start_anaplasma
    #clear all filters
  File "C:\Users\caleb.jones\Repos\nbsbot\env\Lib\site-packages\selenium\webdriver\support\wait.py", line 96, in until
    value = method(self._driver)
  File "C:\Users\caleb.jones\Repos\nbsbot\env\Lib\site-packages\selenium\webdriver\support\expected_conditions.py", line 363, in _predicate
    target = driver.find_element(*target)  # grab element at locator
  File "C:\Users\caleb.jones\Repos\nbsbot\env\Lib\site-packages\selenium\webdriver\remote\webdriver.py", line 770, in find_element
    return self.execute(Command.FIND_ELEMENT, {"using": by, "value": value})["value"]
           ~~~~~~~~~~~~^^^^^^^^^^^^^^^^^^^^^^^^^^^^^^^^^^^^^^^^^^^^^^^^^^^^^
  File "C:\Users\caleb.jones\Repos\nbsbot\env\Lib\site-packages\selenium\webdriver\remote\webdriver.py", line 382, in execute
    response = self.command_executor.execute(driver_command, params)
  File "C:\Users\caleb.jones\Repos\nbsbot\env\Lib\site-packages\selenium\webdriver\remote\remote_connection.py", line 404, in execute
    return self._request(command_info[0], url, body=data)
           ~~~~~~~~~~~~~^^^^^^^^^^^^^^^^^^^^^^^^^^^^^^^^^
  File "C:\Users\caleb.jones\Repos\nbsbot\env\Lib\site-packages\selenium\webdriver\remote\remote_connection.py", line 428, in _request
    response = self._conn.request(method, url, body=body, headers=headers, timeout=self._client_config.timeout)
  File "C:\Users\caleb.jones\Repos\nbsbot\env\Lib\site-packages\urllib3\_request_methods.py", line 143, in request
    return self.request_encode_body(
           ~~~~~~~~~~~~~~~~~~~~~~~~^
        method, url, fields=fields, headers=headers, **urlopen_kw
        ^^^^^^^^^^^^^^^^^^^^^^^^^^^^^^^^^^^^^^^^^^^^^^^^^^^^^^^^^
    )
    ^
  File "C:\Users\caleb.jones\Repos\nbsbot\env\Lib\site-packages\urllib3\_request_methods.py", line 278, in request_encode_body
    return self.urlopen(method, url, **extra_kw)
           ~~~~~~~~~~~~^^^^^^^^^^^^^^^^^^^^^^^^^
  File "C:\Users\caleb.jones\Repos\nbsbot\env\Lib\site-packages\urllib3\poolmanager.py", line 443, in urlopen
    response = conn.urlopen(method, u.request_uri, **kw)
  File "C:\Users\caleb.jones\Repos\nbsbot\env\Lib\site-packages\urllib3\connectionpool.py", line 873, in urlopen
    return self.urlopen(
           ~~~~~~~~~~~~^
        method,
        ^^^^^^^
    ...<13 lines>...
        **response_kw,
        ^^^^^^^^^^^^^^
    )
    ^
  File "C:\Users\caleb.jones\Repos\nbsbot\env\Lib\site-packages\urllib3\connectionpool.py", line 873, in urlopen
    return self.urlopen(
           ~~~~~~~~~~~~^
        method,
        ^^^^^^^
    ...<13 lines>...
        **response_kw,
        ^^^^^^^^^^^^^^
    )
    ^
  File "C:\Users\caleb.jones\Repos\nbsbot\env\Lib\site-packages\urllib3\connectionpool.py", line 873, in urlopen
    return self.urlopen(
           ~~~~~~~~~~~~^
        method,
        ^^^^^^^
    ...<13 lines>...
        **response_kw,
        ^^^^^^^^^^^^^^
    )
    ^
  File "C:\Users\caleb.jones\Repos\nbsbot\env\Lib\site-packages\urllib3\connectionpool.py", line 843, in urlopen
    retries = retries.increment(
        method, url, error=new_e, _pool=self, _stacktrace=sys.exc_info()[2]
    )
  File "C:\Users\caleb.jones\Repos\nbsbot\env\Lib\site-packages\urllib3\util\retry.py", line 519, in increment
    raise MaxRetryError(_pool, url, reason) from reason  # type: ignore[arg-type]
    ^^^^^^^^^^^^^^^^^^^^^^^^^^^^^^^^^^^^^^^^^^^^^^^^^^^
urllib3.exceptions.MaxRetryError: HTTPConnectionPool(host='localhost', port=51466): Max retries exceeded with url: /session/94e441147c81a4d1e5093ed89d511846/element (Caused by NewConnectionError('<urllib3.connection.HTTPConnection object at 0x000001F7842F6EA0>: Failed to establish a new connection: [WinError 10061] No connection could be made because the target machine actively refused it'))
01_09_2025 - list indices must be integers or slices, not NoneType
01_09_2025 - list indices must be integers or slices, not NoneType
01_09_2025 - list indices must be integers or slices, not NoneType
01_09_2025 - list indices must be integers or slices, not function01_10_2025 - unsupported operand type(s) for -: 'list' and 'int'01_10_2025 - name 'code' is not defined