01_14_2025 | anaplasma - Traceback (most recent call last):
  File "C:\Users\caleb.jones\Repos\nbsbot\RevisedBots\decorator.py", line 9, in wrapper_error_handle
    return func(*args)
  File "C:\Users\caleb.jones\Repos\nbsbot\RevisedBots\anaplasma.py", line 196, in start_anaplasma
    NBS.CheckCase()
    ~~~~~~~~~~~~~^^
  File "C:\Users\caleb.jones\Repos\nbsbot\anaplasmacasereview_revised.py", line 330, in CheckCase
    val = str(self.Sero_table["Titer Value"]).split("    ")[1].split(":")
          ~~~~~~~~~~~~~~~~~~~~~~~~~~~~~~~~~~~~~~~~~~~~~~~~~^^^
IndexError: list index out of range

01_14_2025 - 14:16:52.411174 | anaplasma - Traceback (most recent call last):
  File "C:\Users\caleb.jones\Repos\nbsbot\RevisedBots\decorator.py", line 9, in wrapper_error_handle
    return func(*args)
  File "C:\Users\caleb.jones\Repos\nbsbot\RevisedBots\anaplasma.py", line 333, in start_anaplasma
    raise Exception(tb)
Exception: None

01_14_2025 - 14:48:57.141953 | anaplasma - Traceback (most recent call last):
  File "C:\Users\caleb.jones\Repos\nbsbot\RevisedBots\decorator.py", line 9, in wrapper_error_handle
    return func(*args)
  File "C:\Users\caleb.jones\Repos\nbsbot\RevisedBots\anaplasma.py", line 333, in start_anaplasma
    raise Exception(tb)
Exception: None

01_22_2025 - 09:39:34.336114 | audrey - Traceback (most recent call last):
  File "C:\Users\caleb.jones\Repos\nbsbot\env\Lib\site-packages\urllib3\connection.py", line 199, in _new_conn
    sock = connection.create_connection(
        (self._dns_host, self.port),
    ...<2 lines>...
        socket_options=self.socket_options,
    )
  File "C:\Users\caleb.jones\Repos\nbsbot\env\Lib\site-packages\urllib3\util\connection.py", line 85, in create_connection
    raise err
  File "C:\Users\caleb.jones\Repos\nbsbot\env\Lib\site-packages\urllib3\util\connection.py", line 73, in create_connection
    sock.connect(sa)
    ~~~~~~~~~~~~^^^^
ConnectionRefusedError: [WinError 10061] No connection could be made because the target machine actively refused it

The above exception was the direct cause of the following exception:

Traceback (most recent call last):
  File "C:\Users\caleb.jones\Repos\nbsbot\env\Lib\site-packages\urllib3\connectionpool.py", line 789, in urlopen
    response = self._make_request(
        conn,
    ...<10 lines>...
        **response_kw,
    )
  File "C:\Users\caleb.jones\Repos\nbsbot\env\Lib\site-packages\urllib3\connectionpool.py", line 495, in _make_request
    conn.request(
    ~~~~~~~~~~~~^
        method,
        ^^^^^^^
    ...<6 lines>...
        enforce_content_length=enforce_content_length,
        ^^^^^^^^^^^^^^^^^^^^^^^^^^^^^^^^^^^^^^^^^^^^^^
    )
    ^
  File "C:\Users\caleb.jones\Repos\nbsbot\env\Lib\site-packages\urllib3\connection.py", line 441, in request
    self.endheaders()
    ~~~~~~~~~~~~~~~^^
  File "C:\Users\caleb.jones\AppData\Local\Programs\Python\Python313\Lib\http\client.py", line 1331, in endheaders
    self._send_output(message_body, encode_chunked=encode_chunked)
    ~~~~~~~~~~~~~~~~~^^^^^^^^^^^^^^^^^^^^^^^^^^^^^^^^^^^^^^^^^^^^^
  File "C:\Users\caleb.jones\AppData\Local\Programs\Python\Python313\Lib\http\client.py", line 1091, in _send_output
    self.send(msg)
    ~~~~~~~~~^^^^^
  File "C:\Users\caleb.jones\AppData\Local\Programs\Python\Python313\Lib\http\client.py", line 1035, in send
    self.connect()
    ~~~~~~~~~~~~^^
  File "C:\Users\caleb.jones\Repos\nbsbot\env\Lib\site-packages\urllib3\connection.py", line 279, in connect
    self.sock = self._new_conn()
                ~~~~~~~~~~~~~~^^
  File "C:\Users\caleb.jones\Repos\nbsbot\env\Lib\site-packages\urllib3\connection.py", line 214, in _new_conn
    raise NewConnectionError(
        self, f"Failed to establish a new connection: {e}"
    ) from e
urllib3.exceptions.NewConnectionError: <urllib3.connection.HTTPConnection object at 0x000001F7D0F86C40>: Failed to establish a new connection: [WinError 10061] No connection could be made because the target machine actively refused it

The above exception was the direct cause of the following exception:

Traceback (most recent call last):
  File "C:\Users\caleb.jones\Repos\nbsbot\RevisedBots\decorator.py", line 9, in wrapper_error_handle
    return func(*args)
  File "C:\Users\caleb.jones\Repos\nbsbot\RevisedBots\hepatitisbot.py", line 269, in start_audrey
    resulted_test_table = NBS.ReadTableToDF(resulted_test_path)
  File "C:\Users\caleb.jones\Repos\nbsbot\nbsdriver.py", line 417, in ReadTableToDF
    html = self.find_element(By.XPATH, xpath).get_attribute('innerHTML')
           ~~~~~~~~~~~~~~~~~^^^^^^^^^^^^^^^^^
  File "C:\Users\caleb.jones\Repos\nbsbot\env\Lib\site-packages\selenium\webdriver\remote\webdriver.py", line 770, in find_element
    return self.execute(Command.FIND_ELEMENT, {"using": by, "value": value})["value"]
           ~~~~~~~~~~~~^^^^^^^^^^^^^^^^^^^^^^^^^^^^^^^^^^^^^^^^^^^^^^^^^^^^^
  File "C:\Users\caleb.jones\Repos\nbsbot\env\Lib\site-packages\selenium\webdriver\remote\webdriver.py", line 382, in execute
    response = self.command_executor.execute(driver_command, params)
  File "C:\Users\caleb.jones\Repos\nbsbot\env\Lib\site-packages\selenium\webdriver\remote\remote_connection.py", line 404, in execute
    return self._request(command_info[0], url, body=data)
           ~~~~~~~~~~~~~^^^^^^^^^^^^^^^^^^^^^^^^^^^^^^^^^
  File "C:\Users\caleb.jones\Repos\nbsbot\env\Lib\site-packages\selenium\webdriver\remote\remote_connection.py", line 428, in _request
    response = self._conn.request(method, url, body=body, headers=headers, timeout=self._client_config.timeout)
  File "C:\Users\caleb.jones\Repos\nbsbot\env\Lib\site-packages\urllib3\_request_methods.py", line 143, in request
    return self.request_encode_body(
           ~~~~~~~~~~~~~~~~~~~~~~~~^
        method, url, fields=fields, headers=headers, **urlopen_kw
        ^^^^^^^^^^^^^^^^^^^^^^^^^^^^^^^^^^^^^^^^^^^^^^^^^^^^^^^^^
    )
    ^
  File "C:\Users\caleb.jones\Repos\nbsbot\env\Lib\site-packages\urllib3\_request_methods.py", line 278, in request_encode_body
    return self.urlopen(method, url, **extra_kw)
           ~~~~~~~~~~~~^^^^^^^^^^^^^^^^^^^^^^^^^
  File "C:\Users\caleb.jones\Repos\nbsbot\env\Lib\site-packages\urllib3\poolmanager.py", line 443, in urlopen
    response = conn.urlopen(method, u.request_uri, **kw)
  File "C:\Users\caleb.jones\Repos\nbsbot\env\Lib\site-packages\urllib3\connectionpool.py", line 873, in urlopen
    return self.urlopen(
           ~~~~~~~~~~~~^
        method,
        ^^^^^^^
    ...<13 lines>...
        **response_kw,
        ^^^^^^^^^^^^^^
    )
    ^
  File "C:\Users\caleb.jones\Repos\nbsbot\env\Lib\site-packages\urllib3\connectionpool.py", line 873, in urlopen
    return self.urlopen(
           ~~~~~~~~~~~~^
        method,
        ^^^^^^^
    ...<13 lines>...
        **response_kw,
        ^^^^^^^^^^^^^^
    )
    ^
  File "C:\Users\caleb.jones\Repos\nbsbot\env\Lib\site-packages\urllib3\connectionpool.py", line 873, in urlopen
    return self.urlopen(
           ~~~~~~~~~~~~^
        method,
        ^^^^^^^
    ...<13 lines>...
        **response_kw,
        ^^^^^^^^^^^^^^
    )
    ^
  File "C:\Users\caleb.jones\Repos\nbsbot\env\Lib\site-packages\urllib3\connectionpool.py", line 843, in urlopen
    retries = retries.increment(
        method, url, error=new_e, _pool=self, _stacktrace=sys.exc_info()[2]
    )
  File "C:\Users\caleb.jones\Repos\nbsbot\env\Lib\site-packages\urllib3\util\retry.py", line 519, in increment
    raise MaxRetryError(_pool, url, reason) from reason  # type: ignore[arg-type]
    ^^^^^^^^^^^^^^^^^^^^^^^^^^^^^^^^^^^^^^^^^^^^^^^^^^^
urllib3.exceptions.MaxRetryError: HTTPConnectionPool(host='localhost', port=62420): Max retries exceeded with url: /session/0e9d830defd2951d33ce924994dad49e/element (Caused by NewConnectionError('<urllib3.connection.HTTPConnection object at 0x000001F7D0F86C40>: Failed to establish a new connection: [WinError 10061] No connection could be made because the target machine actively refused it'))

01_22_2025 - 10:39:58.081822 | audrey - Traceback (most recent call last):
  File "C:\Users\caleb.jones\Repos\nbsbot\env\Lib\site-packages\urllib3\connection.py", line 199, in _new_conn
    sock = connection.create_connection(
        (self._dns_host, self.port),
    ...<2 lines>...
        socket_options=self.socket_options,
    )
  File "C:\Users\caleb.jones\Repos\nbsbot\env\Lib\site-packages\urllib3\util\connection.py", line 85, in create_connection
    raise err
  File "C:\Users\caleb.jones\Repos\nbsbot\env\Lib\site-packages\urllib3\util\connection.py", line 73, in create_connection
    sock.connect(sa)
    ~~~~~~~~~~~~^^^^
ConnectionRefusedError: [WinError 10061] No connection could be made because the target machine actively refused it

The above exception was the direct cause of the following exception:

Traceback (most recent call last):
  File "C:\Users\caleb.jones\Repos\nbsbot\env\Lib\site-packages\urllib3\connectionpool.py", line 789, in urlopen
    response = self._make_request(
        conn,
    ...<10 lines>...
        **response_kw,
    )
  File "C:\Users\caleb.jones\Repos\nbsbot\env\Lib\site-packages\urllib3\connectionpool.py", line 495, in _make_request
    conn.request(
    ~~~~~~~~~~~~^
        method,
        ^^^^^^^
    ...<6 lines>...
        enforce_content_length=enforce_content_length,
        ^^^^^^^^^^^^^^^^^^^^^^^^^^^^^^^^^^^^^^^^^^^^^^
    )
    ^
  File "C:\Users\caleb.jones\Repos\nbsbot\env\Lib\site-packages\urllib3\connection.py", line 441, in request
    self.endheaders()
    ~~~~~~~~~~~~~~~^^
  File "C:\Users\caleb.jones\AppData\Local\Programs\Python\Python313\Lib\http\client.py", line 1331, in endheaders
    self._send_output(message_body, encode_chunked=encode_chunked)
    ~~~~~~~~~~~~~~~~~^^^^^^^^^^^^^^^^^^^^^^^^^^^^^^^^^^^^^^^^^^^^^
  File "C:\Users\caleb.jones\AppData\Local\Programs\Python\Python313\Lib\http\client.py", line 1091, in _send_output
    self.send(msg)
    ~~~~~~~~~^^^^^
  File "C:\Users\caleb.jones\AppData\Local\Programs\Python\Python313\Lib\http\client.py", line 1035, in send
    self.connect()
    ~~~~~~~~~~~~^^
  File "C:\Users\caleb.jones\Repos\nbsbot\env\Lib\site-packages\urllib3\connection.py", line 279, in connect
    self.sock = self._new_conn()
                ~~~~~~~~~~~~~~^^
  File "C:\Users\caleb.jones\Repos\nbsbot\env\Lib\site-packages\urllib3\connection.py", line 214, in _new_conn
    raise NewConnectionError(
        self, f"Failed to establish a new connection: {e}"
    ) from e
urllib3.exceptions.NewConnectionError: <urllib3.connection.HTTPConnection object at 0x0000022D37326D70>: Failed to establish a new connection: [WinError 10061] No connection could be made because the target machine actively refused it

The above exception was the direct cause of the following exception:

Traceback (most recent call last):
  File "C:\Users\caleb.jones\Repos\nbsbot\RevisedBots\decorator.py", line 9, in wrapper_error_handle
    return func(*args)
  File "C:\Users\caleb.jones\Repos\nbsbot\RevisedBots\hepatitisbot.py", line 72, in start_audrey
    WebDriverWait(NBS,NBS.wait_before_timeout).until(EC.element_to_be_clickable((By.PARTIAL_LINK_TEXT, partial_link)))
    ~~~~~~~~~~~~~~~~~~~~~~~~~~~~~~~~~~~~~~~~~~~~~~~~^^^^^^^^^^^^^^^^^^^^^^^^^^^^^^^^^^^^^^^^^^^^^^^^^^^^^^^^^^^^^^^^^^
  File "C:\Users\caleb.jones\Repos\nbsbot\env\Lib\site-packages\selenium\webdriver\support\wait.py", line 96, in until
    value = method(self._driver)
  File "C:\Users\caleb.jones\Repos\nbsbot\env\Lib\site-packages\selenium\webdriver\support\expected_conditions.py", line 363, in _predicate
    target = driver.find_element(*target)  # grab element at locator
  File "C:\Users\caleb.jones\Repos\nbsbot\env\Lib\site-packages\selenium\webdriver\remote\webdriver.py", line 770, in find_element
    return self.execute(Command.FIND_ELEMENT, {"using": by, "value": value})["value"]
           ~~~~~~~~~~~~^^^^^^^^^^^^^^^^^^^^^^^^^^^^^^^^^^^^^^^^^^^^^^^^^^^^^
  File "C:\Users\caleb.jones\Repos\nbsbot\env\Lib\site-packages\selenium\webdriver\remote\webdriver.py", line 382, in execute
    response = self.command_executor.execute(driver_command, params)
  File "C:\Users\caleb.jones\Repos\nbsbot\env\Lib\site-packages\selenium\webdriver\remote\remote_connection.py", line 404, in execute
    return self._request(command_info[0], url, body=data)
           ~~~~~~~~~~~~~^^^^^^^^^^^^^^^^^^^^^^^^^^^^^^^^^
  File "C:\Users\caleb.jones\Repos\nbsbot\env\Lib\site-packages\selenium\webdriver\remote\remote_connection.py", line 428, in _request
    response = self._conn.request(method, url, body=body, headers=headers, timeout=self._client_config.timeout)
  File "C:\Users\caleb.jones\Repos\nbsbot\env\Lib\site-packages\urllib3\_request_methods.py", line 143, in request
    return self.request_encode_body(
           ~~~~~~~~~~~~~~~~~~~~~~~~^
        method, url, fields=fields, headers=headers, **urlopen_kw
        ^^^^^^^^^^^^^^^^^^^^^^^^^^^^^^^^^^^^^^^^^^^^^^^^^^^^^^^^^
    )
    ^
  File "C:\Users\caleb.jones\Repos\nbsbot\env\Lib\site-packages\urllib3\_request_methods.py", line 278, in request_encode_body
    return self.urlopen(method, url, **extra_kw)
           ~~~~~~~~~~~~^^^^^^^^^^^^^^^^^^^^^^^^^
  File "C:\Users\caleb.jones\Repos\nbsbot\env\Lib\site-packages\urllib3\poolmanager.py", line 443, in urlopen
    response = conn.urlopen(method, u.request_uri, **kw)
  File "C:\Users\caleb.jones\Repos\nbsbot\env\Lib\site-packages\urllib3\connectionpool.py", line 873, in urlopen
    return self.urlopen(
           ~~~~~~~~~~~~^
        method,
        ^^^^^^^
    ...<13 lines>...
        **response_kw,
        ^^^^^^^^^^^^^^
    )
    ^
  File "C:\Users\caleb.jones\Repos\nbsbot\env\Lib\site-packages\urllib3\connectionpool.py", line 873, in urlopen
    return self.urlopen(
           ~~~~~~~~~~~~^
        method,
        ^^^^^^^
    ...<13 lines>...
        **response_kw,
        ^^^^^^^^^^^^^^
    )
    ^
  File "C:\Users\caleb.jones\Repos\nbsbot\env\Lib\site-packages\urllib3\connectionpool.py", line 873, in urlopen
    return self.urlopen(
           ~~~~~~~~~~~~^
        method,
        ^^^^^^^
    ...<13 lines>...
        **response_kw,
        ^^^^^^^^^^^^^^
    )
    ^
  File "C:\Users\caleb.jones\Repos\nbsbot\env\Lib\site-packages\urllib3\connectionpool.py", line 843, in urlopen
    retries = retries.increment(
        method, url, error=new_e, _pool=self, _stacktrace=sys.exc_info()[2]
    )
  File "C:\Users\caleb.jones\Repos\nbsbot\env\Lib\site-packages\urllib3\util\retry.py", line 519, in increment
    raise MaxRetryError(_pool, url, reason) from reason  # type: ignore[arg-type]
    ^^^^^^^^^^^^^^^^^^^^^^^^^^^^^^^^^^^^^^^^^^^^^^^^^^^
urllib3.exceptions.MaxRetryError: HTTPConnectionPool(host='localhost', port=51881): Max retries exceeded with url: /session/2a86be5081ca80633a58016dc8e7cf0a/element (Caused by NewConnectionError('<urllib3.connection.HTTPConnection object at 0x0000022D37326D70>: Failed to establish a new connection: [WinError 10061] No connection could be made because the target machine actively refused it'))

01_30_2025 - 06:17:22.769925 | anaplasma - Traceback (most recent call last):
  File "C:\Users\caleb.jones\Repos\nbsbot\RevisedBots\anaplasma.py", line 99, in start_anaplasma
    WebDriverWait(NBS,NBS.wait_before_timeout).until(EC.element_to_be_clickable((By.XPATH, '/html/body/div[2]/form/div/table[2]/tbody/tr/td/table/thead/tr/th[8]/div/label[1]/input[1]')))
    ~~~~~~~~~~~~~~~~~~~~~~~~~~~~~~~~~~~~~~~~~~~~~~~~^^^^^^^^^^^^^^^^^^^^^^^^^^^^^^^^^^^^^^^^^^^^^^^^^^^^^^^^^^^^^^^^^^^^^^^^^^^^^^^^^^^^^^^^^^^^^^^^^^^^^^^^^^^^^^^^^^^^^^^^^^^^^^^^^^^^^^
  File "C:\Users\caleb.jones\Repos\nbsbot\env\Lib\site-packages\selenium\webdriver\support\wait.py", line 105, in until
    raise TimeoutException(message, screen, stacktrace)
selenium.common.exceptions.TimeoutException: Message: 


During handling of the above exception, another exception occurred:

Traceback (most recent call last):
  File "C:\Users\caleb.jones\Repos\nbsbot\env\Lib\site-packages\urllib3\connectionpool.py", line 789, in urlopen
    response = self._make_request(
        conn,
    ...<10 lines>...
        **response_kw,
    )
  File "C:\Users\caleb.jones\Repos\nbsbot\env\Lib\site-packages\urllib3\connectionpool.py", line 536, in _make_request
    response = conn.getresponse()
  File "C:\Users\caleb.jones\Repos\nbsbot\env\Lib\site-packages\urllib3\connection.py", line 507, in getresponse
    httplib_response = super().getresponse()
  File "C:\Users\caleb.jones\AppData\Local\Programs\Python\Python313\Lib\http\client.py", line 1428, in getresponse
    response.begin()
    ~~~~~~~~~~~~~~^^
  File "C:\Users\caleb.jones\AppData\Local\Programs\Python\Python313\Lib\http\client.py", line 331, in begin
    version, status, reason = self._read_status()
                              ~~~~~~~~~~~~~~~~~^^
  File "C:\Users\caleb.jones\AppData\Local\Programs\Python\Python313\Lib\http\client.py", line 292, in _read_status
    line = str(self.fp.readline(_MAXLINE + 1), "iso-8859-1")
               ~~~~~~~~~~~~~~~~^^^^^^^^^^^^^^
  File "C:\Users\caleb.jones\AppData\Local\Programs\Python\Python313\Lib\socket.py", line 719, in readinto
    return self._sock.recv_into(b)
           ~~~~~~~~~~~~~~~~~~~~^^^
ConnectionResetError: [WinError 10054] An existing connection was forcibly closed by the remote host

During handling of the above exception, another exception occurred:

Traceback (most recent call last):
  File "C:\Users\caleb.jones\Repos\nbsbot\RevisedBots\anaplasma.py", line 104, in start_anaplasma
    NBS.find_element(By.XPATH,'/html/body/div[2]/form/div/table[2]/tbody/tr/td/table/thead/tr/th[8]/div/label[1]/input[2]').click()
    ~~~~~~~~~~~~~~~~~~~~~~~~~~~~~~~~~~~~~~~~~~~~~~~~~~~~~~~~~~~~~~~~~~~~~~~~~~~~~~~~~~~~~~~~~~~~~~~~~~~~~~~~~~~~~~~~~~~~~~~~~~~~~^^
  File "C:\Users\caleb.jones\Repos\nbsbot\env\Lib\site-packages\selenium\webdriver\remote\webelement.py", line 94, in click
    self._execute(Command.CLICK_ELEMENT)
    ~~~~~~~~~~~~~^^^^^^^^^^^^^^^^^^^^^^^
  File "C:\Users\caleb.jones\Repos\nbsbot\env\Lib\site-packages\selenium\webdriver\remote\webelement.py", line 395, in _execute
    return self._parent.execute(command, params)
           ~~~~~~~~~~~~~~~~~~~~^^^^^^^^^^^^^^^^^
  File "C:\Users\caleb.jones\Repos\nbsbot\env\Lib\site-packages\selenium\webdriver\remote\webdriver.py", line 382, in execute
    response = self.command_executor.execute(driver_command, params)
  File "C:\Users\caleb.jones\Repos\nbsbot\env\Lib\site-packages\selenium\webdriver\remote\remote_connection.py", line 404, in execute
    return self._request(command_info[0], url, body=data)
           ~~~~~~~~~~~~~^^^^^^^^^^^^^^^^^^^^^^^^^^^^^^^^^
  File "C:\Users\caleb.jones\Repos\nbsbot\env\Lib\site-packages\selenium\webdriver\remote\remote_connection.py", line 428, in _request
    response = self._conn.request(method, url, body=body, headers=headers, timeout=self._client_config.timeout)
  File "C:\Users\caleb.jones\Repos\nbsbot\env\Lib\site-packages\urllib3\_request_methods.py", line 143, in request
    return self.request_encode_body(
           ~~~~~~~~~~~~~~~~~~~~~~~~^
        method, url, fields=fields, headers=headers, **urlopen_kw
        ^^^^^^^^^^^^^^^^^^^^^^^^^^^^^^^^^^^^^^^^^^^^^^^^^^^^^^^^^
    )
    ^
  File "C:\Users\caleb.jones\Repos\nbsbot\env\Lib\site-packages\urllib3\_request_methods.py", line 278, in request_encode_body
    return self.urlopen(method, url, **extra_kw)
           ~~~~~~~~~~~~^^^^^^^^^^^^^^^^^^^^^^^^^
  File "C:\Users\caleb.jones\Repos\nbsbot\env\Lib\site-packages\urllib3\poolmanager.py", line 443, in urlopen
    response = conn.urlopen(method, u.request_uri, **kw)
  File "C:\Users\caleb.jones\Repos\nbsbot\env\Lib\site-packages\urllib3\connectionpool.py", line 843, in urlopen
    retries = retries.increment(
        method, url, error=new_e, _pool=self, _stacktrace=sys.exc_info()[2]
    )
  File "C:\Users\caleb.jones\Repos\nbsbot\env\Lib\site-packages\urllib3\util\retry.py", line 474, in increment
    raise reraise(type(error), error, _stacktrace)
          ~~~~~~~^^^^^^^^^^^^^^^^^^^^^^^^^^^^^^^^^
  File "C:\Users\caleb.jones\Repos\nbsbot\env\Lib\site-packages\urllib3\util\util.py", line 38, in reraise
    raise value.with_traceback(tb)
  File "C:\Users\caleb.jones\Repos\nbsbot\env\Lib\site-packages\urllib3\connectionpool.py", line 789, in urlopen
    response = self._make_request(
        conn,
    ...<10 lines>...
        **response_kw,
    )
  File "C:\Users\caleb.jones\Repos\nbsbot\env\Lib\site-packages\urllib3\connectionpool.py", line 536, in _make_request
    response = conn.getresponse()
  File "C:\Users\caleb.jones\Repos\nbsbot\env\Lib\site-packages\urllib3\connection.py", line 507, in getresponse
    httplib_response = super().getresponse()
  File "C:\Users\caleb.jones\AppData\Local\Programs\Python\Python313\Lib\http\client.py", line 1428, in getresponse
    response.begin()
    ~~~~~~~~~~~~~~^^
  File "C:\Users\caleb.jones\AppData\Local\Programs\Python\Python313\Lib\http\client.py", line 331, in begin
    version, status, reason = self._read_status()
                              ~~~~~~~~~~~~~~~~~^^
  File "C:\Users\caleb.jones\AppData\Local\Programs\Python\Python313\Lib\http\client.py", line 292, in _read_status
    line = str(self.fp.readline(_MAXLINE + 1), "iso-8859-1")
               ~~~~~~~~~~~~~~~~^^^^^^^^^^^^^^
  File "C:\Users\caleb.jones\AppData\Local\Programs\Python\Python313\Lib\socket.py", line 719, in readinto
    return self._sock.recv_into(b)
           ~~~~~~~~~~~~~~~~~~~~^^^
urllib3.exceptions.ProtocolError: ('Connection aborted.', ConnectionResetError(10054, 'An existing connection was forcibly closed by the remote host', None, 10054, None))

During handling of the above exception, another exception occurred:

Traceback (most recent call last):
  File "C:\Users\caleb.jones\Repos\nbsbot\RevisedBots\decorator.py", line 9, in wrapper_error_handle
    return func(*args)
  File "C:\Users\caleb.jones\Repos\nbsbot\RevisedBots\anaplasma.py", line 300, in start_anaplasma
    raise Exception(e)
Exception: ('Connection aborted.', ConnectionResetError(10054, 'An existing connection was forcibly closed by the remote host', None, 10054, None))

01_30_2025 - 06:22:25.231396 | anaplasma - Traceback (most recent call last):
  File "C:\Users\caleb.jones\Repos\nbsbot\env\Lib\site-packages\urllib3\connectionpool.py", line 789, in urlopen
    response = self._make_request(
        conn,
    ...<10 lines>...
        **response_kw,
    )
  File "C:\Users\caleb.jones\Repos\nbsbot\env\Lib\site-packages\urllib3\connectionpool.py", line 536, in _make_request
    response = conn.getresponse()
  File "C:\Users\caleb.jones\Repos\nbsbot\env\Lib\site-packages\urllib3\connection.py", line 507, in getresponse
    httplib_response = super().getresponse()
  File "C:\Users\caleb.jones\AppData\Local\Programs\Python\Python313\Lib\http\client.py", line 1428, in getresponse
    response.begin()
    ~~~~~~~~~~~~~~^^
  File "C:\Users\caleb.jones\AppData\Local\Programs\Python\Python313\Lib\http\client.py", line 331, in begin
    version, status, reason = self._read_status()
                              ~~~~~~~~~~~~~~~~~^^
  File "C:\Users\caleb.jones\AppData\Local\Programs\Python\Python313\Lib\http\client.py", line 292, in _read_status
    line = str(self.fp.readline(_MAXLINE + 1), "iso-8859-1")
               ~~~~~~~~~~~~~~~~^^^^^^^^^^^^^^
  File "C:\Users\caleb.jones\AppData\Local\Programs\Python\Python313\Lib\socket.py", line 719, in readinto
    return self._sock.recv_into(b)
           ~~~~~~~~~~~~~~~~~~~~^^^
ConnectionResetError: [WinError 10054] An existing connection was forcibly closed by the remote host

During handling of the above exception, another exception occurred:

Traceback (most recent call last):
  File "C:\Users\caleb.jones\Repos\nbsbot\RevisedBots\anaplasma.py", line 99, in start_anaplasma
    WebDriverWait(NBS,NBS.wait_before_timeout).until(EC.element_to_be_clickable((By.XPATH, '/html/body/div[2]/form/div/table[2]/tbody/tr/td/table/thead/tr/th[8]/div/label[1]/input[1]')))
    ~~~~~~~~~~~~~~~~~~~~~~~~~~~~~~~~~~~~~~~~~~~~~~~~^^^^^^^^^^^^^^^^^^^^^^^^^^^^^^^^^^^^^^^^^^^^^^^^^^^^^^^^^^^^^^^^^^^^^^^^^^^^^^^^^^^^^^^^^^^^^^^^^^^^^^^^^^^^^^^^^^^^^^^^^^^^^^^^^^^^^^
  File "C:\Users\caleb.jones\Repos\nbsbot\env\Lib\site-packages\selenium\webdriver\support\wait.py", line 96, in until
    value = method(self._driver)
  File "C:\Users\caleb.jones\Repos\nbsbot\env\Lib\site-packages\selenium\webdriver\support\expected_conditions.py", line 364, in _predicate
    element = visibility_of(target)(driver)
  File "C:\Users\caleb.jones\Repos\nbsbot\env\Lib\site-packages\selenium\webdriver\support\expected_conditions.py", line 173, in _predicate
    return _element_if_visible(element)
  File "C:\Users\caleb.jones\Repos\nbsbot\env\Lib\site-packages\selenium\webdriver\support\expected_conditions.py", line 179, in _element_if_visible
    return element if element.is_displayed() == visibility else False
                      ~~~~~~~~~~~~~~~~~~~~^^
  File "C:\Users\caleb.jones\Repos\nbsbot\env\Lib\site-packages\selenium\webdriver\remote\webelement.py", line 252, in is_displayed
    return self.parent.execute_script(f"/* isDisplayed */return ({isDisplayed_js}).apply(null, arguments);", self)
           ~~~~~~~~~~~~~~~~~~~~~~~~~~^^^^^^^^^^^^^^^^^^^^^^^^^^^^^^^^^^^^^^^^^^^^^^^^^^^^^^^^^^^^^^^^^^^^^^^^^^^^^
  File "C:\Users\caleb.jones\Repos\nbsbot\env\Lib\site-packages\selenium\webdriver\remote\webdriver.py", line 444, in execute_script
    return self.execute(command, {"script": script, "args": converted_args})["value"]
           ~~~~~~~~~~~~^^^^^^^^^^^^^^^^^^^^^^^^^^^^^^^^^^^^^^^^^^^^^^^^^^^^^
  File "C:\Users\caleb.jones\Repos\nbsbot\env\Lib\site-packages\selenium\webdriver\remote\webdriver.py", line 382, in execute
    response = self.command_executor.execute(driver_command, params)
  File "C:\Users\caleb.jones\Repos\nbsbot\env\Lib\site-packages\selenium\webdriver\remote\remote_connection.py", line 404, in execute
    return self._request(command_info[0], url, body=data)
           ~~~~~~~~~~~~~^^^^^^^^^^^^^^^^^^^^^^^^^^^^^^^^^
  File "C:\Users\caleb.jones\Repos\nbsbot\env\Lib\site-packages\selenium\webdriver\remote\remote_connection.py", line 428, in _request
    response = self._conn.request(method, url, body=body, headers=headers, timeout=self._client_config.timeout)
  File "C:\Users\caleb.jones\Repos\nbsbot\env\Lib\site-packages\urllib3\_request_methods.py", line 143, in request
    return self.request_encode_body(
           ~~~~~~~~~~~~~~~~~~~~~~~~^
        method, url, fields=fields, headers=headers, **urlopen_kw
        ^^^^^^^^^^^^^^^^^^^^^^^^^^^^^^^^^^^^^^^^^^^^^^^^^^^^^^^^^
    )
    ^
  File "C:\Users\caleb.jones\Repos\nbsbot\env\Lib\site-packages\urllib3\_request_methods.py", line 278, in request_encode_body
    return self.urlopen(method, url, **extra_kw)
           ~~~~~~~~~~~~^^^^^^^^^^^^^^^^^^^^^^^^^
  File "C:\Users\caleb.jones\Repos\nbsbot\env\Lib\site-packages\urllib3\poolmanager.py", line 443, in urlopen
    response = conn.urlopen(method, u.request_uri, **kw)
  File "C:\Users\caleb.jones\Repos\nbsbot\env\Lib\site-packages\urllib3\connectionpool.py", line 843, in urlopen
    retries = retries.increment(
        method, url, error=new_e, _pool=self, _stacktrace=sys.exc_info()[2]
    )
  File "C:\Users\caleb.jones\Repos\nbsbot\env\Lib\site-packages\urllib3\util\retry.py", line 474, in increment
    raise reraise(type(error), error, _stacktrace)
          ~~~~~~~^^^^^^^^^^^^^^^^^^^^^^^^^^^^^^^^^
  File "C:\Users\caleb.jones\Repos\nbsbot\env\Lib\site-packages\urllib3\util\util.py", line 38, in reraise
    raise value.with_traceback(tb)
  File "C:\Users\caleb.jones\Repos\nbsbot\env\Lib\site-packages\urllib3\connectionpool.py", line 789, in urlopen
    response = self._make_request(
        conn,
    ...<10 lines>...
        **response_kw,
    )
  File "C:\Users\caleb.jones\Repos\nbsbot\env\Lib\site-packages\urllib3\connectionpool.py", line 536, in _make_request
    response = conn.getresponse()
  File "C:\Users\caleb.jones\Repos\nbsbot\env\Lib\site-packages\urllib3\connection.py", line 507, in getresponse
    httplib_response = super().getresponse()
  File "C:\Users\caleb.jones\AppData\Local\Programs\Python\Python313\Lib\http\client.py", line 1428, in getresponse
    response.begin()
    ~~~~~~~~~~~~~~^^
  File "C:\Users\caleb.jones\AppData\Local\Programs\Python\Python313\Lib\http\client.py", line 331, in begin
    version, status, reason = self._read_status()
                              ~~~~~~~~~~~~~~~~~^^
  File "C:\Users\caleb.jones\AppData\Local\Programs\Python\Python313\Lib\http\client.py", line 292, in _read_status
    line = str(self.fp.readline(_MAXLINE + 1), "iso-8859-1")
               ~~~~~~~~~~~~~~~~^^^^^^^^^^^^^^
  File "C:\Users\caleb.jones\AppData\Local\Programs\Python\Python313\Lib\socket.py", line 719, in readinto
    return self._sock.recv_into(b)
           ~~~~~~~~~~~~~~~~~~~~^^^
urllib3.exceptions.ProtocolError: ('Connection aborted.', ConnectionResetError(10054, 'An existing connection was forcibly closed by the remote host', None, 10054, None))

During handling of the above exception, another exception occurred:

Traceback (most recent call last):
  File "C:\Users\caleb.jones\Repos\nbsbot\RevisedBots\decorator.py", line 9, in wrapper_error_handle
    return func(*args)
  File "C:\Users\caleb.jones\Repos\nbsbot\RevisedBots\anaplasma.py", line 300, in start_anaplasma
    raise Exception(e)
Exception: ('Connection aborted.', ConnectionResetError(10054, 'An existing connection was forcibly closed by the remote host', None, 10054, None))

01_30_2025 - 06:33:07.357560 | anaplasma - Traceback (most recent call last):
  File "C:\Users\caleb.jones\Repos\nbsbot\env\Lib\site-packages\urllib3\connectionpool.py", line 789, in urlopen
    response = self._make_request(
        conn,
    ...<10 lines>...
        **response_kw,
    )
  File "C:\Users\caleb.jones\Repos\nbsbot\env\Lib\site-packages\urllib3\connectionpool.py", line 536, in _make_request
    response = conn.getresponse()
  File "C:\Users\caleb.jones\Repos\nbsbot\env\Lib\site-packages\urllib3\connection.py", line 507, in getresponse
    httplib_response = super().getresponse()
  File "C:\Users\caleb.jones\AppData\Local\Programs\Python\Python313\Lib\http\client.py", line 1428, in getresponse
    response.begin()
    ~~~~~~~~~~~~~~^^
  File "C:\Users\caleb.jones\AppData\Local\Programs\Python\Python313\Lib\http\client.py", line 331, in begin
    version, status, reason = self._read_status()
                              ~~~~~~~~~~~~~~~~~^^
  File "C:\Users\caleb.jones\AppData\Local\Programs\Python\Python313\Lib\http\client.py", line 292, in _read_status
    line = str(self.fp.readline(_MAXLINE + 1), "iso-8859-1")
               ~~~~~~~~~~~~~~~~^^^^^^^^^^^^^^
  File "C:\Users\caleb.jones\AppData\Local\Programs\Python\Python313\Lib\socket.py", line 719, in readinto
    return self._sock.recv_into(b)
           ~~~~~~~~~~~~~~~~~~~~^^^
ConnectionResetError: [WinError 10054] An existing connection was forcibly closed by the remote host

During handling of the above exception, another exception occurred:

Traceback (most recent call last):
  File "C:\Users\caleb.jones\Repos\nbsbot\RevisedBots\anaplasma.py", line 76, in start_anaplasma
    WebDriverWait(NBS,NBS.wait_before_timeout).until(EC.presence_of_element_located((By.XPATH, condition_path)))
    ~~~~~~~~~~~~~~~~~~~~~~~~~~~~~~~~~~~~~~~~~~~~~~~~^^^^^^^^^^^^^^^^^^^^^^^^^^^^^^^^^^^^^^^^^^^^^^^^^^^^^^^^^^^^
  File "C:\Users\caleb.jones\Repos\nbsbot\env\Lib\site-packages\selenium\webdriver\support\wait.py", line 96, in until
    value = method(self._driver)
  File "C:\Users\caleb.jones\Repos\nbsbot\env\Lib\site-packages\selenium\webdriver\support\expected_conditions.py", line 84, in _predicate
    return driver.find_element(*locator)
           ~~~~~~~~~~~~~~~~~~~^^^^^^^^^^
  File "C:\Users\caleb.jones\Repos\nbsbot\env\Lib\site-packages\selenium\webdriver\remote\webdriver.py", line 770, in find_element
    return self.execute(Command.FIND_ELEMENT, {"using": by, "value": value})["value"]
           ~~~~~~~~~~~~^^^^^^^^^^^^^^^^^^^^^^^^^^^^^^^^^^^^^^^^^^^^^^^^^^^^^
  File "C:\Users\caleb.jones\Repos\nbsbot\env\Lib\site-packages\selenium\webdriver\remote\webdriver.py", line 382, in execute
    response = self.command_executor.execute(driver_command, params)
  File "C:\Users\caleb.jones\Repos\nbsbot\env\Lib\site-packages\selenium\webdriver\remote\remote_connection.py", line 404, in execute
    return self._request(command_info[0], url, body=data)
           ~~~~~~~~~~~~~^^^^^^^^^^^^^^^^^^^^^^^^^^^^^^^^^
  File "C:\Users\caleb.jones\Repos\nbsbot\env\Lib\site-packages\selenium\webdriver\remote\remote_connection.py", line 428, in _request
    response = self._conn.request(method, url, body=body, headers=headers, timeout=self._client_config.timeout)
  File "C:\Users\caleb.jones\Repos\nbsbot\env\Lib\site-packages\urllib3\_request_methods.py", line 143, in request
    return self.request_encode_body(
           ~~~~~~~~~~~~~~~~~~~~~~~~^
        method, url, fields=fields, headers=headers, **urlopen_kw
        ^^^^^^^^^^^^^^^^^^^^^^^^^^^^^^^^^^^^^^^^^^^^^^^^^^^^^^^^^
    )
    ^
  File "C:\Users\caleb.jones\Repos\nbsbot\env\Lib\site-packages\urllib3\_request_methods.py", line 278, in request_encode_body
    return self.urlopen(method, url, **extra_kw)
           ~~~~~~~~~~~~^^^^^^^^^^^^^^^^^^^^^^^^^
  File "C:\Users\caleb.jones\Repos\nbsbot\env\Lib\site-packages\urllib3\poolmanager.py", line 443, in urlopen
    response = conn.urlopen(method, u.request_uri, **kw)
  File "C:\Users\caleb.jones\Repos\nbsbot\env\Lib\site-packages\urllib3\connectionpool.py", line 843, in urlopen
    retries = retries.increment(
        method, url, error=new_e, _pool=self, _stacktrace=sys.exc_info()[2]
    )
  File "C:\Users\caleb.jones\Repos\nbsbot\env\Lib\site-packages\urllib3\util\retry.py", line 474, in increment
    raise reraise(type(error), error, _stacktrace)
          ~~~~~~~^^^^^^^^^^^^^^^^^^^^^^^^^^^^^^^^^
  File "C:\Users\caleb.jones\Repos\nbsbot\env\Lib\site-packages\urllib3\util\util.py", line 38, in reraise
    raise value.with_traceback(tb)
  File "C:\Users\caleb.jones\Repos\nbsbot\env\Lib\site-packages\urllib3\connectionpool.py", line 789, in urlopen
    response = self._make_request(
        conn,
    ...<10 lines>...
        **response_kw,
    )
  File "C:\Users\caleb.jones\Repos\nbsbot\env\Lib\site-packages\urllib3\connectionpool.py", line 536, in _make_request
    response = conn.getresponse()
  File "C:\Users\caleb.jones\Repos\nbsbot\env\Lib\site-packages\urllib3\connection.py", line 507, in getresponse
    httplib_response = super().getresponse()
  File "C:\Users\caleb.jones\AppData\Local\Programs\Python\Python313\Lib\http\client.py", line 1428, in getresponse
    response.begin()
    ~~~~~~~~~~~~~~^^
  File "C:\Users\caleb.jones\AppData\Local\Programs\Python\Python313\Lib\http\client.py", line 331, in begin
    version, status, reason = self._read_status()
                              ~~~~~~~~~~~~~~~~~^^
  File "C:\Users\caleb.jones\AppData\Local\Programs\Python\Python313\Lib\http\client.py", line 292, in _read_status
    line = str(self.fp.readline(_MAXLINE + 1), "iso-8859-1")
               ~~~~~~~~~~~~~~~~^^^^^^^^^^^^^^
  File "C:\Users\caleb.jones\AppData\Local\Programs\Python\Python313\Lib\socket.py", line 719, in readinto
    return self._sock.recv_into(b)
           ~~~~~~~~~~~~~~~~~~~~^^^
urllib3.exceptions.ProtocolError: ('Connection aborted.', ConnectionResetError(10054, 'An existing connection was forcibly closed by the remote host', None, 10054, None))

During handling of the above exception, another exception occurred:

Traceback (most recent call last):
  File "C:\Users\caleb.jones\Repos\nbsbot\RevisedBots\decorator.py", line 9, in wrapper_error_handle
    return func(*args)
  File "C:\Users\caleb.jones\Repos\nbsbot\RevisedBots\anaplasma.py", line 300, in start_anaplasma
    raise Exception(e)
Exception: ('Connection aborted.', ConnectionResetError(10054, 'An existing connection was forcibly closed by the remote host', None, 10054, None))

